Workbook

Sheet STATUS
A1: c-ECO RESEARCH PROTOCOL — SCREENING STAGE | Method FROZEN v1.3 | File v1.3.3 (data-corrected, live formulas)
A3: This workbook operationalizes the screening stage of the review protocol.
A4: The review protocol is frozen as of Version 1.3. Subsequent changes are restricted to data corrections, source verification, and corpus expansion.
A5: It is NOT a preliminary triage. It is a formal methodological artifact with
A6: governance structure: STATUS, matrix, codebook, corpus summary, analytical results,
A7: H3 co-presence, hypotheses, coding manual, decision log, and functional architecture.
A9: c-ECO is intentionally excluded (bias control); it is positioned separately in Paper 2.
A11: Corrected conclusion (use this wording):
A12: The preliminary screening suggests a fragmentation pattern: financial macroprudential frameworks are
A13: operational but sector-specific, while cross-sectoral and threshold-oriented frameworks remain weak on
A14: executable decision protocols and reversibility. Among the corpus, only ONE entry is an operational system,
A15: so coverage claims are reported WITHIN type classes, not across the full set. This pattern requires
... A96: requiring local recalculation.

Sheet Review Matrix
A1: ID | B1: Article / Framework | C1: Authors / Source | D1: Year | E1: Type (orig) | F1: Type_v2 | G1: Construct scope | H1: Publication status | I1: Sector | J1: Integration mechanism | K1: F1 Op.Arch | L1: F2 Decision | M1: F3 Cross-Sec | N1: F4 Threshold | O1: F5 Observ | P1: F6 Ex-Ante | Q1: F7 Revers | R1: Total | S1: C1 | T1: C2 | U1: C3 | V1: C4 | W1: C5 | X1: C6 | Y1: C7 | Z1: Explicit limitation (abstract-derived, UNVERIFIED) | AA1: Limitation verify status | AB1: Source / DOI / link | AC1: Status | AD1: all>=2 | AE1: all>=1
A2: 1 | B2: Macroprudential systemic-risk apparatus (ESRB/ECB) + IMF Growth-at-Risk | C2: ESRB/ECB; Adrian et al. | D2: 2011- | E2: Operational System | F2: Operational System | G2: core | H2: peer-reviewed | I2: Finance | J2: Financial-stability indicators + capital buffers | K2: 3 | L2: 3 | M2: 1 | N2: 2 | O2: 3 | P2: 3 | Q2: 1 | R2: =SUM(K2:Q2) -> 16 | S2: Full institutional design: indicators, roles, process defined (SRISK, CCyB). | T2: Executable triggers: capital buffer activation thresholds, ESRB warnings. | U2: Finance-only. No cross-sector coupling (energy, water, transport). | V2: Dynamic thresholds (CCyB cyclical), but not proximity/velocity model. | W2: Leading indicators validated (credit gaps, asset prices). | X2: Acts before crisis: countercyclical buffers, early intervention. | Y2: Reversibility not treated as decision variable; assumes financial losses are reversible. | Z2: "The macroprudential approach is designed for the financial system and its direct spillovers. Physical infrastructure interdependencies are outside its scope." [verify: ESRB Annual Report 2013, p. 12] | AA2: abstract-paraphrase — verify page+quote | AB2: https://www.esrb.europa.eu; Adrian et al. (2019) JF | AC2: Provisional (verify) | AD2: =IF(MIN(K2:Q2)>=2,1,0) -> 0 | AE2: =IF(MIN(K2:Q2)>=1,1,0) -> 1
A3: 2 | B3: Planetary Boundaries / Safe Operating Space | C3: Rockström et al.; Steffen et al. | D3: 2009 | E3: Theory | F3: Theory | G3: core | H3: peer-reviewed | I3: Earth system / environment | J3: Planetary control variables vs. limits | K3: 1 | L3: 0 | M3: 3 | N3: 3 | O3: 2 | P3: 2 | Q3: 2 | R3: =SUM(K3:Q3) -> 13 | S3: Conceptual architecture (control variables), but no institutional design. | T3: No executable trigger; boundaries are diagnostic, not prescriptive. | U3: Generic Earth-system framework: climate, biodiversity, nitrogen, etc. inherently cross-sector. | V3: Dynamic thresholds (control variables with uncertainty zones), but no velocity model. | W3: Observability via remote sensing, but not validated as leading indicators with pre-event detection. | X3: Values acting early (precaution), but no institutional decision protocol. | Y3: Acknowledges irreversibility (e.g., biodiversity loss), but not as operational decision variable. | Z3: "Planetary boundaries do not prescribe policies or governance mechanisms; they are a scientific diagnostic framework." [Rockström et al. 2009, Nature, p. 472] | AA3: abstract-paraphrase — verify page+quote | AB3: 10.1038/461472a; 10.1126/science.1259855 (Steffen 2015) | AC3: Provisional (verify) | AD3: =IF(MIN(K3:Q3)>=2,1,0) -> 0 | AE3: =IF(MIN(K3:Q3)>=1,1,0) -> 0
A4: 3 | B4: Interdependent networks (percolation / cascades) | C4: Buldyrev, Havlin et al. | D4: 2010 | E4: Method | F4: Method | G4: core | H4: peer-reviewed | I4: Networks (generic) | J4: Coupled-network percolation model | K4: 0 | L4: 0 | M4: 3 | N4: 3 | O4: 1 | P4: 0 | Q4: 1 | R4: =SUM(K4:Q4) -> 8 | S4: No institutional design; purely mathematical model. | T4: No decision protocol; model describes failure, not governance. | U4: Generic coupled networks applicable to any interdependent system. | V4: Percolation threshold as critical point; dynamic in the sense of phase transition. | W4: Percolation metric as indicator, but not validated as leading indicator. | X4: No governance dimension; purely descriptive. | Y4: Collapse is irreversible in model, but not treated as decision variable. | Z4: "The model does not address how to prevent or govern the cascade; it characterizes the conditions under which it occurs." [Buldyrev et al. 2010, Nature, p. 1027] | AA4: abstract-paraphrase — verify page+quote | AB4: 10.1038/nature08932 | AC4: Provisional (verify) | AD4: =IF(MIN(K4:Q4)>=2,1,0) -> 0 | AE4: =IF(MIN(K4:Q4)>=1,1,0) -> 0
A5: 4 | B5: Critical-infrastructure interdependencies | C5: Rinaldi et al. | D5: 2001 | E5: Framework | F5: Framework | G5: core | H5: peer-reviewed | I5: Critical infrastructure | J5: Interdependency taxonomy (physical, cyber, geographic, logical) | K5: 1 | L5: 0 | M5: 3 | N5: 1 | O5: 1 | P5: 1 | Q5: 0 | R5: =SUM(K5:Q5) -> 7 | S5: Taxonomy framework, not operational design. | T5: No executable trigger; classification only. | U5: Cross-sector by definition (energy, telecom, water, transport). | V5: Mentions cascading thresholds qualitatively, no dynamic model. | W5: Mentions monitoring needs, no validated indicators. | X5: Implicit (protect infrastructure), no explicit ex-ante protocol. | Y5: Not addressed. | Z5: "This paper develops a taxonomy and modeling framework, not an operational governance protocol." [Rinaldi et al. 2001, IEEE Control Systems, p. 15] | AA5: abstract-paraphrase — verify page+quote | AB5: 10.1109/MCS.2001.954849 | AC5: Provisional (verify) | AD5: =IF(MIN(K5:Q5)>=2,1,0) -> 0 | AE5: =IF(MIN(K5:Q5)>=1,1,0) -> 0
A6: 5 | B6: Critical slowing down / early-warning signals | C6: Scheffer et al.; Dakos et al. | D6: 2009 | E6: Method | F6: Method | G6: core | H6: peer-reviewed | I6: Ecology / climate (generic) | J6: Statistical leading indicators of transition | K6: 1 | L6: 1 | M6: 2 | N6: 3 | O6: 3 | P6: 2 | Q6: 1 | R6: =SUM(K6:Q6) -> 13 | S6: Methodological architecture (variance, autocorrelation, skewness), not institutional. | T6: Recommends action when signals detected, but no formal trigger mechanism. | U6: Generic method applicable across domains, but no cross-sector integration mechanism. | V6: Dynamic threshold: critical slowing down as proximity-to-tipping indicator. | W6: Leading indicators validated (variance, autocorrelation increase before tipping). | X6: Values early action, but no institutional decision protocol. | Y6: Acknowledges tipping points as irreversible, but not as decision variable. | Z6: "Early-warning signals indicate proximity to a threshold, but do not prescribe what action to take or who should take it." [Scheffer et al. 2009, Nature, p. 53] | AA6: abstract-paraphrase — verify page+quote | AB6: 10.1038/nature08227; 10.1073/pnas.0702430104 | AC6: Provisional (verify) | AD6: =IF(MIN(K6:Q6)>=2,1,0) -> 0 | AE6: =IF(MIN(K6:Q6)>=1,1,0) -> 1
A7: 6 | B7: Resilience engineering / HRO | C7: Hollnagel; Weick & Sutcliffe | D7: 2006 | E7: Framework | F7: Framework | G7: core | H7: peer-reviewed | I7: Safety-critical engineering | J7: Resilience / high-reliability practices (anticipation, monitoring, response, learning) | K7: 2 | L7: 2 | M7: 2 | N7: 1 | O7: 2 | P7: 2 | Q7: 1 | R7: =SUM(K7:Q7) -> 12 | S7: Resilience practices defined (monitoring, response, learning), but not as formal architecture. | T7: Decision protocols exist (HRO: deference to expertise, preoccupation with failure), but not as executable triggers. | U7: Primarily safety-critical domains (aviation, nuclear, healthcare); limited cross-sector. | V7: No explicit threshold model; resilience is about coping with surprise, not predicting thresholds. | W7: Monitoring is central (preoccupation with failure), but not leading indicators. | X7: Anticipation is a core principle, but not formalized as pre-threshold decision protocol. | Y7: Not addressed; resilience assumes recovery is possible. | Z7: "Resilience engineering focuses on coping with surprise and recovery, not on predicting and preventing threshold crossings." [Hollnagel et al. 2006, Resilience Engineering, p. 8] | AA7: abstract-paraphrase — verify page+quote | AB7: Hollnagel et al. (2006) Resilience Engineering: Concepts and Precepts; Weick & Sutcliffe (2007) Managing the Unexpected | AC7: Provisional (verify) | AD7: =IF(MIN(K7:Q7)>=2,1,0) -> 0 | AE7: =IF(MIN(K7:Q7)>=1,1,0) -> 1
A8: 7 | B8: Sendai Framework / disaster-risk governance | C8: UNDRR | D8: 2015 | E8: Policy | F8: Policy | G8: core | H8: policy report | I8: Disaster risk (multi-sector) | J8: DRR policy cycle (risk assessment, prevention, preparedness, response, recovery) | K8: 2 | L8: 2 | M8: 3 | N8: 1 | O8: 2 | P8: 2 | Q8: 1 | R8: =SUM(K8:Q8) -> 13 | S8: Policy architecture defined (4 priorities, targets), but not operational design. | T8: Decision protocols at national level (DRR strategies), but not executable triggers. | U8: Multi-sector by design (health, infrastructure, environment, economy). | V8: Mentions systemic risk, but no dynamic threshold model. | W8: Early warning as priority, but not validated leading indicators. | X8: Prevention and preparedness prioritized, but not formalized as pre-threshold governance. | Y8: Build back better implies reversibility concerns, but not as explicit variable. | Z8: "The Sendai Framework is a policy instrument, not an operational technical framework for threshold-based governance." [UNDRR 2015, Sendai Framework, p. 12] | AA8: abstract-paraphrase — verify page+quote | AB8: UNDRR (2015) Sendai Framework for Disaster Risk Reduction 2015-2030 | AC8: Provisional (verify) | AD8: =IF(MIN(K8:Q8)>=2,1,0) -> 0 | AE8: =IF(MIN(K8:Q8)>=1,1,0) -> 1
A9: 8 | B9: Anticipatory / adaptive governance | C9: Guston; Folke; Ostrom | D9: 2008- | E9: Theory | F9: Theory | G9: core | H9: peer-reviewed | I9: Governance (generic) | J9: Anticipation / deliberation / adaptation / polycentric governance | K9: 1 | L9: 1 | M9: 2 | N9: 1 | O9: 1 | P9: 3 | Q9: 2 | R9: =SUM(K9:Q9) -> 11 | S9: Theoretical principles (anticipation, deliberation), not operational architecture. | T9: Deliberation and foresight, but no executable trigger mechanism. | U9: Polycentric governance implies multi-level, but not necessarily cross-sector. | V9: Adaptive cycle (Panarchy) has thresholds, but not operationalized. | W9: Monitoring is part of adaptive management, but not leading indicators. | X9: Anticipation is the core concept; acts before crisis via deliberation. | Y9: Regime shifts acknowledged as potentially irreversible, but not as decision variable. | Z9: "Anticipatory governance is a theoretical orientation, not a ready-to-use operational protocol for infrastructure systems." [Guston 2014, Journal of Responsible Innovation, p. 2] | AA9: abstract-paraphrase — verify page+quote | AB9: Guston (2014) J. Responsible Innovation; Folke (2006) Ecology & Society; Ostrom (2009) Science | AC9: Provisional (verify) | AD9: =IF(MIN(K9:Q9)>=2,1,0) -> 0 | AE9: =IF(MIN(K9:Q9)>=1,1,0) -> 1
A10: 9 | B10: ISO 31000 / NIST CSF risk-management standards | C10: ISO; NIST | D10: 2018 | E10: Standard | F10: Standard | G10: core | H10: standard | I10: Cross-domain risk mgmt | J10: Generic risk-management process (identify, assess, treat, monitor) | K10: 2 | L10: 2 | M10: 2 | N10: 1 | O10: 2 | P10: 2 | Q10: 1 | R10: =SUM(K10:Q10) -> 12 | S10: Process architecture defined (risk management process), but not specific to systemic thresholds. | T10: Risk treatment decisions, but not threshold-based triggers. | U10: Generic cross-domain, but no interdependency mechanism. | V10: Risk appetite/limits, but not dynamic threshold dynamics. | W10: Monitoring and review required, but not leading indicators. | X10: Prevention is a risk treatment option, but not formalized as ex-ante governance. | Y10: Risk tolerance implies reversibility, but not as explicit variable. | Z10: "ISO 31000 provides a generic risk management framework, not a domain-specific operational system for interdependent infrastructure." [ISO 31000:2018, Introduction, p. v] | AA10: abstract-paraphrase — verify page+quote | AB10: ISO 31000:2018; NIST CSF 1.1 | AC10: Provisional (verify) | AD10: =IF(MIN(K10:Q10)>=2,1,0) -> 0 | AE10: =IF(MIN(K10:Q10)>=1,1,0) -> 1
A11: 10 | B11: Systemic risk in banking: a survey | C11: De Bandt, Hartmann | D11: 2002 | E11: Theory | F11: Review/Survey | G11: core | H11: peer-reviewed | I11: Finance | J11: Contagion channels + interbank exposure | K11: 2 | L11: 1 | M11: 1 | N11: 2 | O11: 2 | P11: 1 | Q11: 0 | R11: =SUM(K11:Q11) -> 9 | S11: Survey of contagion mechanisms; institutional design discussed but not specified. | T11: Recommends lender-of-last-resort, but no executable trigger. | U11: Banking sector only. | V11: Contagion thresholds discussed, but not dynamic proximity model. | W11: Interbank exposure data used, but not leading indicators. | X11: Post-crisis intervention (LLR), not pre-threshold. | Y11: Not addressed. | Z11: "We do not address the operational design of macroprudential governance frameworks." [De Bandt & Hartmann 2002, p. 270] | AA11: abstract-paraphrase — verify page+quote | AB11: 10.1023/A:1021204814240 | AC11: Provisional (verify) | AD11: =IF(MIN(K11:Q11)>=2,1,0) -> 0 | AE11: =IF(MIN(K11:Q11)>=1,1,0) -> 0
A12: 11 | B12: Network models of financial systemic risk: a review | C12: Caccioli, Barucca, Kobayashi | D12: 2018 | E12: Theory | F12: Review/Survey | G12: core | H12: peer-reviewed | I12: Finance | J12: Network contagion models | K12: 1 | L12: 0 | M12: 1 | N12: 2 | O12: 2 | P12: 0 | Q12: 0 | R12: =SUM(K12:Q12) -> 6 | S12: Modeling framework, not operational architecture. | T12: No decision protocol. | U12: Financial networks only. | V12: Contagion thresholds in network models. | W12: Network metrics as indicators, but not validated leading indicators. | X12: No governance dimension. | Y12: Not addressed. | Z12: "Network models of systemic risk have focused on characterization rather than on the design of governance interventions." [Caccioli et al. 2018, p. 1] | AA12: abstract-paraphrase — verify page+quote | AB12: 10.1007/s42001-017-0008-3 | AC12: Provisional (verify) | AD12: =IF(MIN(K12:Q12)>=2,1,0) -> 0 | AE12: =IF(MIN(K12:Q12)>=1,1,0) -> 0
A13: 12 | B13: Macroprudential policy: a literature review | C13: Galati, Moessner | D13: 2013 | E13: Theory | F13: Review/Survey | G13: core | H13: peer-reviewed | I13: Finance | J13: Macroprudential instruments (capital buffers, LTV limits) | K13: 2 | L13: 2 | M13: 1 | N13: 2 | O13: 2 | P13: 2 | Q13: 1 | R13: =SUM(K13:Q13) -> 12 | S13: Instruments catalogued, but not as unified operational architecture. | T13: Instruments activated, but triggers vary by country. | U13: Finance only. | V13: Credit-gap thresholds, but not dynamic proximity model. | W13: Credit gaps as leading indicators, validated. | X13: Countercyclical by design, but timing not always explicit. | Y13: Losses assumed reversible; no explicit reversibility window. | Z13: "Macroprudential policy has been developed for the financial sector and its direct spillovers; its application to physical infrastructure is unexplored." [Galati & Moessner 2013, p. 1] | AA13: abstract-paraphrase — verify page+quote | AB13: 10.1111/j.1467-6419.2012.00729.x | AC13: Provisional (verify) | AD13: =IF(MIN(K13:Q13)>=2,1,0) -> 0 | AE13: =IF(MIN(K13:Q13)>=1,1,0) -> 1
... A61: 60 | B61: Machine learning applications in ICIS resilience: systematic review | C61: Alkhaleel | D61: 2024 | E61: Method | F61: Review/Survey | G61: core | H61: peer-reviewed | I61: Critical infrastructure | J61: ML for resilience assessment + prediction | K61: 1 | L61: 0 | M61: 2 | N61: 2 | O61: 2 | P61: 0 | Q61: 0 | R61: =SUM(K61:Q61) -> 7 | S61: ML methods, not operational architecture. | T61: No decision protocol. | U61: Interdependent CI systems. | V61: ML for threshold prediction. | W61: ML as observability tool. | X61: No governance. | Y61: Not addressed. | Z61: "ML applications improve resilience assessment but do not integrate with governance decision-making protocols." [Alkhaleel 2024, IJCIP, p. 1] | AA61: abstract-paraphrase — verify page+quote | AB61: 10.1016/j.ijcip.2023.100059 | AC61: Provisional (verify) | AD61: =IF(MIN(K61:Q61)>=2,1,0) -> 0 | AE61: =IF(MIN(K61:Q61)>=1,1,0) -> 0

Sheet Codebook
A1: Function codebook — score reflects what a work DEMONSTRATES, not what it claims
A3: Function | B3: 0 — Absent | C3: 1 — Conceptual | D3: 2 — Partial/non-actionable | E3: 3 — Complete & actionable | F3: Boundary note
A4: F1 Operational Architecture | B4: No design | C4: Implementation discussed abstractly | D4: Indicators/steps, no action | E4: Triggers, roles, actions defined | F4: Design layer
A5: F2 Decision Protocol | B5: No protocol | C5: Recommends action | D5: Partial/informal trigger | E5: Executable trigger: who acts, on what criterion | F5: Mechanism, not timing
A6: F3 Cross-Sector Integration | B6: Single sector | C6: One sector, mentions others | D6: Two sectors coupled | E6: Generic to >=3 interdependent sectors | F6: —
A7: F4 Threshold Dynamics | B7: No threshold | C7: Qualitative/metaphorical | D7: Quantified but static | E7: Dynamic: proximity, velocity, uncertainty | F7: NB: ML probability cutoff != threshold dynamics
A8: F5 Observability | B8: No monitoring | C8: Indicators proposed | D8: Validated in one domain | E8: Leading indicators + pre-event detection | F8: —
A9: F6 Ex-Ante Governance | B9: Post-hoc/recovery | C9: Values acting early | D9: Partial preventive protocol | E9: Decision before critical point, explicit criteria | F9: Timing, not mechanism
A10: F7 Reversibility | B10: Ignores | C10: Cites irreversibility | D10: Distinguishes reversible/irreversible | E10: Reversibility window as decision variable | F10: Only F7=3 is an unverified AI preprint

Sheet H3 Co-presence
A1: H3 — Functional co-presence matrix (computed by formula) v1.2
A3: RULE: "present" = score >= 2 (substantive, actionable presence). Cells = CONDITIONAL share P(row present | column present) = count(both>=2) / count(column>=2). Diagonal = base rate count(>=2).
A5: CRITICAL NOTE v1.2: This matrix measures CO-OCCURRENCE only. It does NOT establish:
A6: • Causal direction (which function "causes" or "requires" another)
A7: • Logical necessity (whether functions are structurally dependent)
A8: • Derivational structure (whether one function can be derived from another)
A10: To evaluate H3 fully, additional evidence is needed: qualitative coding, logical analysis, structural derivation.
A12: METHODLOGICAL TENSION: The scoring protocol treats F1-F7 as independently codable. H3 tests whether this independence assumption is false. These operate at different epistemic levels.
A15: P(row | col) | B15: F1 Op.Arch | C15: F2 Decision | D15: F3 Cross-Sec | E15: F4 Threshold | F15: F5 Observ | G15: F6 Ex-Ante | H15: F7 Revers
A16: F1 Op.Arch | B16: =COUNTIF('Review Matrix'!K2:K61,">=2") -> 22 | C16: =IFERROR(COUNTIFS('Review Matrix'!K2:K61,">=2",'Review Matrix'!L2:L61,">=2")/COUNTIF('Review Matrix'!L2:L61,">=2"),0) -> 1 | D16: =IFERROR(COUNTIFS('Review Matrix'!K2:K61,">=2",'Review Matrix'!M2:M61,">=2")/COUNTIF('Review Matrix'!M2:M61,">=2"),0) -> 0.25806452 | E16: =IFERROR(COUNTIFS('Review Matrix'!K2:K61,">=2",'Review Matrix'!N2:N61,">=2")/COUNTIF('Review Matrix'!N2:N61,">=2"),0) -> 0.39393939 | F16: =IFERROR(COUNTIFS('Review Matrix'!K2:K61,">=2",'Review Matrix'!O2:O61,">=2")/COUNTIF('Review Matrix'!O2:O61,">=2"),0) -> 0.66666667 | G16: =IFERROR(COUNTIFS('Review Matrix'!K2:K61,">=2",'Review Matrix'!P2:P61,">=2")/COUNTIF('Review Matrix'!P2:P61,">=2"),0) -> 0.52 | H16: =IFERROR(COUNTIFS('Review Matrix'!K2:K61,">=2",'Review Matrix'!Q2:Q61,">=2")/COUNTIF('Review Matrix'!Q2:Q61,">=2"),0) -> 0.16666667
A17: F2 Decision | B17: =IFERROR(COUNTIFS('Review Matrix'!L2:L61,">=2",'Review Matrix'!K2:K61,">=2")/COUNTIF('Review Matrix'!K2:K61,">=2"),0) -> 0.5 | C17: =COUNTIF('Review Matrix'!L2:L61,">=2") -> 11 | D17: =IFERROR(COUNTIFS('Review Matrix'!L2:L61,">=2",'Review Matrix'!M2:M61,">=2")/COUNTIF('Review Matrix'!M2:M61,">=2"),0) -> 0.096774194 | E17: =IFERROR(COUNTIFS('Review Matrix'!L2:L61,">=2",'Review Matrix'!N2:N61,">=2")/COUNTIF('Review Matrix'!N2:N61,">=2"),0) -> 0.21212121 | F17: =IFERROR(COUNTIFS('Review Matrix'!L2:L61,">=2",'Review Matrix'!O2:O61,">=2")/COUNTIF('Review Matrix'!O2:O61,">=2"),0) -> 0.37037037 | G17: =IFERROR(COUNTIFS('Review Matrix'!L2:L61,">=2",'Review Matrix'!P2:P61,">=2")/COUNTIF('Review Matrix'!P2:P61,">=2"),0) -> 0.36 | H17: =IFERROR(COUNTIFS('Review Matrix'!L2:L61,">=2",'Review Matrix'!Q2:Q61,">=2")/COUNTIF('Review Matrix'!Q2:Q61,">=2"),0) -> 0.16666667
A18: F3 Cross-Sec | B18: =IFERROR(COUNTIFS('Review Matrix'!M2:M61,">=2",'Review Matrix'!K2:K61,">=2")/COUNTIF('Review Matrix'!K2:K61,">=2"),0) -> 0.36363636 | C18: =IFERROR(COUNTIFS('Review Matrix'!M2:M61,">=2",'Review Matrix'!L2:L61,">=2")/COUNTIF('Review Matrix'!L2:L61,">=2"),0) -> 0.27272727 | D18: =COUNTIF('Review Matrix'!M2:M61,">=2") -> 31 | E18: =IFERROR(COUNTIFS('Review Matrix'!M2:M61,">=2",'Review Matrix'!N2:N61,">=2")/COUNTIF('Review Matrix'!N2:N61,">=2"),0) -> 0.51515152 | F18: =IFERROR(COUNTIFS('Review Matrix'!M2:M61,">=2",'Review Matrix'!O2:O61,">=2")/COUNTIF('Review Matrix'!O2:O61,">=2"),0) -> 0.51851852 | G18: =IFERROR(COUNTIFS('Review Matrix'!M2:M61,">=2",'Review Matrix'!P2:P61,">=2")/COUNTIF('Review Matrix'!P2:P61,">=2"),0) -> 0.4 | H18: =IFERROR(COUNTIFS('Review Matrix'!M2:M61,">=2",'Review Matrix'!Q2:Q61,">=2")/COUNTIF('Review Matrix'!Q2:Q61,">=2"),0) -> 0.33333333
A19: F4 Threshold | B19: =IFERROR(COUNTIFS('Review Matrix'!N2:N61,">=2",'Review Matrix'!K2:K61,">=2")/COUNTIF('Review Matrix'!K2:K61,">=2"),0) -> 0.59090909 | C19: =IFERROR(COUNTIFS('Review Matrix'!N2:N61,">=2",'Review Matrix'!L2:L61,">=2")/COUNTIF('Review Matrix'!L2:L61,">=2"),0) -> 0.63636364 | D19: =IFERROR(COUNTIFS('Review Matrix'!N2:N61,">=2",'Review Matrix'!M2:M61,">=2")/COUNTIF('Review Matrix'!M2:M61,">=2"),0) -> 0.5483871 | E19: =COUNTIF('Review Matrix'!N2:N61,">=2") -> 33 | F19: =IFERROR(COUNTIFS('Review Matrix'!N2:N61,">=2",'Review Matrix'!O2:O61,">=2")/COUNTIF('Review Matrix'!O2:O61,">=2"),0) -> 0.74074074 | G19: =IFERROR(COUNTIFS('Review Matrix'!N2:N61,">=2",'Review Matrix'!P2:P61,">=2")/COUNTIF('Review Matrix'!P2:P61,">=2"),0) -> 0.48 | H19: =IFERROR(COUNTIFS('Review Matrix'!N2:N61,">=2",'Review Matrix'!Q2:Q61,">=2")/COUNTIF('Review Matrix'!Q2:Q61,">=2"),0) -> 0.5
A20: F5 Observ | B20: =IFERROR(COUNTIFS('Review Matrix'!O2:O61,">=2",'Review Matrix'!K2:K61,">=2")/COUNTIF('Review Matrix'!K2:K61,">=2"),0) -> 0.81818182 | C20: =IFERROR(COUNTIFS('Review Matrix'!O2:O61,">=2",'Review Matrix'!L2:L61,">=2")/COUNTIF('Review Matrix'!L2:L61,">=2"),0) -> 0.90909091 | D20: =IFERROR(COUNTIFS('Review Matrix'!O2:O61,">=2",'Review Matrix'!M2:M61,">=2")/COUNTIF('Review Matrix'!M2:M61,">=2"),0) -> 0.4516129 | E20: =IFERROR(COUNTIFS('Review Matrix'!O2:O61,">=2",'Review Matrix'!N2:N61,">=2")/COUNTIF('Review Matrix'!N2:N61,">=2"),0) -> 0.60606061 | F20: =COUNTIF('Review Matrix'!O2:O61,">=2") -> 27 | G20: =IFERROR(COUNTIFS('Review Matrix'!O2:O61,">=2",'Review Matrix'!P2:P61,">=2")/COUNTIF('Review Matrix'!P2:P61,">=2"),0) -> 0.52 | H20: =IFERROR(COUNTIFS('Review Matrix'!O2:O61,">=2",'Review Matrix'!Q2:Q61,">=2")/COUNTIF('Review Matrix'!Q2:Q61,">=2"),0) -> 0.16666667
A21: F6 Ex-Ante | B21: =IFERROR(COUNTIFS('Review Matrix'!P2:P61,">=2",'Review Matrix'!K2:K61,">=2")/COUNTIF('Review Matrix'!K2:K61,">=2"),0) -> 0.59090909 | C21: =IFERROR(COUNTIFS('Review Matrix'!P2:P61,">=2",'Review Matrix'!L2:L61,">=2")/COUNTIF('Review Matrix'!L2:L61,">=2"),0) -> 0.81818182 | D21: =IFERROR(COUNTIFS('Review Matrix'!P2:P61,">=2",'Review Matrix'!M2:M61,">=2")/COUNTIF('Review Matrix'!M2:M61,">=2"),0) -> 0.32258065 | E21: =IFERROR(COUNTIFS('Review Matrix'!P2:P61,">=2",'Review Matrix'!N2:N61,">=2")/COUNTIF('Review Matrix'!N2:N61,">=2"),0) -> 0.36363636 | F21: =IFERROR(COUNTIFS('Review Matrix'!P2:P61,">=2",'Review Matrix'!O2:O61,">=2")/COUNTIF('Review Matrix'!O2:O61,">=2"),0) -> 0.48148148 | G21: =COUNTIF('Review Matrix'!P2:P61,">=2") -> 25 | H21: =IFERROR(COUNTIFS('Review Matrix'!P2:P61,">=2",'Review Matrix'!Q2:Q61,">=2")/COUNTIF('Review Matrix'!Q2:Q61,">=2"),0) -> 0.66666667
A22: F7 Revers | B22: =IFERROR(COUNTIFS('Review Matrix'!Q2:Q61,">=2",'Review Matrix'!K2:K61,">=2")/COUNTIF('Review Matrix'!K2:K61,">=2"),0) -> 0.045454545 | C22: =IFERROR(COUNTIFS('Review Matrix'!Q2:Q61,">=2",'Review Matrix'!L2:L61,">=2")/COUNTIF('Review Matrix'!L2:L61,">=2"),0) -> 0.090909091 | D22: =IFERROR(COUNTIFS('Review Matrix'!Q2:Q61,">=2",'Review Matrix'!M2:M61,">=2")/COUNTIF('Review Matrix'!M2:M61,">=2"),0) -> 0.064516129 | E22: =IFERROR(COUNTIFS('Review Matrix'!Q2:Q61,">=2",'Review Matrix'!N2:N61,">=2")/COUNTIF('Review Matrix'!N2:N61,">=2"),0) -> 0.090909091 | F22: =IFERROR(COUNTIFS('Review Matrix'!Q2:Q61,">=2",'Review Matrix'!O2:O61,">=2")/COUNTIF('Review Matrix'!O2:O61,">=2"),0) -> 0.037037037 | G22: =IFERROR(COUNTIFS('Review Matrix'!Q2:Q61,">=2",'Review Matrix'!P2:P61,">=2")/COUNTIF('Review Matrix'!P2:P61,">=2"),0) -> 0.16 | H22: =COUNTIF('Review Matrix'!Q2:Q61,">=2") -> 6
A24: Diagonal = number of frameworks scoring >=2 on that function (base rate).
A25: Dependency test for H3: read columns. If P(Fi | Fj) is high but P(Fj | Fi) is low, Fj tends to require Fi (directional dependency).

Sheet Hypotheses
A1: Hypotheses — preliminary screening (n=60). NOT confirmation. v1.2
A3: Hypothesis | B3: Statement | C3: Preliminary reading | D3: Status
A4: H1 | B4: No single framework satisfies all 7 integration functions. | C4: Preliminary pattern consistent with H1: 0/60 score >=2 on all 7 (formula: Statistics). NB driven partly by type-mix; read within type class. | D4: Preliminary pattern (not confirmed)
A5: H2 | B5: Shortfalls of the strongest frameworks are systematically opposed (sectoral depth vs cross-sector activation). | C5: Preliminary pattern consistent with H2: finance (ESRB, Lund-Jensen) strong F1/F2/F5 but F3=1; socio-ecological (Planetary, anticipatory gov.) strong F3/F6 but weak F1/F2. | D5: Preliminary pattern (not confirmed)
A6: H3 | B6: The 7 functions have a necessary dependency structure, not an arbitrary set. | C6: The co-presence analysis measures only ONE component of H3 (co-occurrence). It is INSUFFICIENT ALONE to evaluate the logical necessity or derivational structure claimed in H3. Additional evidence (qualitative coding, logical analysis, structural derivation) is required. See H3 Co-presence tab for co-occurrence data. Bayesian network analysis or DAG estimation may provide COMPLEMENTARY insight, but are not required to sustain or refute H3. | D6: To be tested (co-presence alone insufficient)

Sheet Corpus Summary
A1: CORPUS SUMMARY v1.3 — DESCRIPTIVE STATISTICS ONLY
A2: No interpretation. No causal claims. Frequencies, types, and publication metadata.
A4: A. DISTRIBUTION OF SCORES BY FUNCTION (ordinal frequencies)
A5: Function | B5: 0 (Absent) | C5: 1 (Conceptual) | D5: 2 (Partial) | E5: 3 (Complete) | F5: Total
A6: F1 Op.Arch | B6: 3 | C6: 35 | D6: 21 | E6: 1 | F6: 60
A7: F2 Decision | B7: 17 | C7: 32 | D7: 10 | E7: 1 | F7: 60
A8: F3 Cross-Sec | B8: 0 | C8: 29 | D8: 15 | E8: 16 | F8: 60
A9: F4 Threshold | B9: 0 | C9: 27 | D9: 28 | E9: 5 | F9: 60
A10: F5 Observ | B10: 1 | C10: 32 | D10: 21 | E10: 6 | F10: 60
A11: F6 Ex-Ante | B11: 14 | C11: 21 | D11: 20 | E11: 5 | F11: 60
A12: F7 Revers | B12: 28 | C12: 26 | D12: 5 | E12: 1 | F12: 60
A14: B. TYPE DISTRIBUTION (Type_v2)
A15: Type | B15: Count | C15: %
A16: Theory | B16: 26 | C16: 43.3%
A17: Review/Survey | B17: 13 | C17: 21.7%
A18: Method | B18: 9 | C18: 15.0%
A19: Framework | B19: 8 | C19: 13.3%
A20: Policy | B20: 2 | C20: 3.3%
A21: Operational System | B21: 1 | C21: 1.7%
A22: Standard | B22: 1 | C22: 1.7%
A23: Total | B23: 60 | C23: 100%
A25: C. PUBLICATION STATUS
A26: Status | B26: Count | C26: % | D26: Flag
A27: peer-reviewed | B27: 43 | C27: 71.7% | D27: ✓
A28: preprint | B28: 7 | C28: 11.7% | D28: ⚠️ VERIFY
A29: unknown (verify) | B29: 4 | C29: 6.7% | D29: ⚠️ VERIFY
A30: working paper | B30: 3 | C30: 5.0%
A31: policy report | B31: 2 | C31: 3.3%
A32: standard | B32: 1 | C32: 1.7%
A33: Total | B33: 60 | C33: 100%
A35: D. CONSTRUCT SCOPE
A36: Scope | B36: Count | C36: % | D36: Note
A37: core | B37: 54 | C37: 90.0% | D37: Carry F3/F7 expectations
A38: adjacent (ML cutoff) | B38: 6 | C38: 10.0% | D38: Do not carry F3/F7 expectations
A40: E. SECTOR DISTRIBUTION
A41: Sector | B41: Count | C41: %
A42: Critical infrastructure | B42: 8 | C42: 13.3%
A43: Finance | B43: 5 | C43: 8.3%
A44: Global (multi-domain) | B44: 4 | C44: 6.7%
A45: Disaster risk (multi-sector) | B45: 3 | C45: 5.0%
...

Sheet Analytical Results
A1: ANALYTICAL RESULTS v1.3 — INTERPRETATION SEPARATED FROM DESCRIPTION
A2: All claims here are interpretive. They require confirmation through full-text coding, verbatim extraction, and corpus expansion.
A4: 1. PATTERN: Fragmentation by sectoral depth vs. cross-sector activation
A6: Observation | B6: Evidence | C6: Interpretation | D6: Confidence | E6: Needs confirmation
A7: Financial frameworks (ESRB, Adrian, Lund-Jensen) score high on F1, F2, F5, F6 but F3=1. | B7: IDs 1, 12, 39 | C7: Finance has operational depth but no cross-sector coupling. | D7: Moderate (n=3) | E7: Expand finance corpus; verify if any finance framework crosses to F3≥2
A8: Socio-ecological frameworks (Planetary Boundaries, Anticipatory Gov.) score high on F3, F6 but low on F1, F2. | B8: IDs 2, 8, 41, 42 | C8: Cross-sector vision exists but lacks operational architecture and executable triggers. | D8: Moderate (n=4) | E8: Verify if any socio-ecological framework has F1≥2 or F2≥2
A9: No framework bridges the gap between sectoral depth and cross-sector operationalization. | B9: 0/60 have all 7 ≥ 2 | C9: The gap may be structural, not merely a sampling artifact. | D9: Low (n=60) | E9: Expand to 150; test with different sampling strategy
A11: 2. PATTERN: Decision Protocol (F2) and Reversibility (F7) are the most deficit functions
A13: Observation | B13: Evidence | C13: Interpretation | D13: Confidence | E13: Needs confirmation
A14: F2 has 32 conceptual (1) vs 1 complete (3). | B14: Distribution table | C14: The literature talks about deciding but rarely operationalizes who decides, on what criterion, with what action. | D14: Moderate | E14: Full-text coding of F2=1 entries to see if they mention decision abstractly
A15: F7 has 26 conceptual (1) vs 1 complete (3), and that one is an AI preprint. | B15: Distribution table | C15: Reversibility is recognized as a concept but almost never operationalized as a decision variable in infrastructure. | D15: Moderate | E15: Verify if any infrastructure framework (not AI) scores F7≥2
A16: F2 and F7 rarely co-occur at score ≥ 2. | B16: H3 Co-presence: P(F7|F2)=9.1% | C16: Decision protocols and reversibility thinking are functionally separate in the literature. | D16: Low | E16: Test with expanded corpus; may be sampling artifact
A18: 3. PATTERN: Observability (F5) and Threshold Dynamics (F4) co-occur frequently
A20: Observation | B20: Evidence | C20: Interpretation | D20: Confidence | E20: Needs confirmation
A21: P(F5|F4) = 60.6% and P(F4|F5) = 74.1%. | B21: H3 Co-presence matrix | C21: Frameworks that model thresholds tend to also propose indicators. This is a descriptive association, not a causal claim. | D21: Moderate | E21: Verify with full-text coding; check if F4 and F5 are measured in the same empirical system or separately
A23: 4. PATTERN: Only one Operational System in the corpus
A25: Observation | B25: Evidence | C25: Interpretation | D25: Confidence | E25: Needs confirmation
A26: Only ID 1 (ESRB/ECB) is classified as Operational System. | B26: Type_v2 count | C26: The corpus is heavily theoretical. Coverage claims must be read within type classes, not across the full set. | D26: High | E26: Verify if other frameworks should be reclassified; search for additional operational systems
A28: 5. PATTERN: Adjacent constructs (ML/AI) do not fill the gap
A30: Observation | B30: Evidence | C30: Interpretation | D30: Confidence | E30: Needs confirmation
A31: 6 ML/AI preprints score on F1, F2, F4 but are isolated from infrastructure. | B31: IDs 45-49, 55 | C31: The adjacent domain (AI governance) explores similar concepts but does not transfer to physical infrastructure interdependencies. | D31: Moderate | E31: Verify if any AI governance framework explicitly addresses infrastructure; check for cross-citation
A33: 6. LIMITATIONS OF THIS ANALYSIS
A35: Limitation | B35: Impact | C35: Mitigation
A36: n=60 is small for pattern detection. | B36: Patterns may be sampling artifacts. | C36: Expand to ~150 frameworks.
A37: Scores are provisional (a-priori hypotheses). | B37: May not reflect full-text content. | C37: Full-text coding with Coding Manual.
A38: Only one coder (no inter-coder reliability). | B38: Subjectivity uncontrolled. | C38: Add second coder; compute Cohen's kappa.
A39: 7 preprints + 4 unknown publications. | B39: Evidence quality uncertain. | C39: Verify all; exclude or downgrade if unverifiable.
A40: English-language search only. | B40: Omission bias for non-English literature. | C40: Search Portuguese, Spanish, Chinese sources.
A42: 7. EMERGENT FUNCTIONAL ARCHITECTURE (RQ1 draft)
A44: From the corpus, the strongest observed combination per function is:
A45: F1: ESRB/ECB (3) — institutional design with indicators, roles, process
A46: F2: ESRB/ECB (3) — executable trigger with actor, criterion, action
A47: F3: Planetary Boundaries / Buldyrev / Rinaldi (3) — generic cross-sector applicability
A48: F4: Scheffer/Dakos / Schäfer / Planetary Boundaries / Lund-Jensen (3) — dynamic proximity model
A49: F5: Scheffer/Dakos / Velazquez / Lund-Jensen / Wever (3) — validated leading indicators with pre-event detection
A50: F6: ESRB/ECB / Boyd / Muiderman / Fuerth (3) — anticipatory governance with explicit pre-event criteria
A51: F7: Duseja 2026 (3) — reversibility window as explicit decision variable, BUT: AI preprint, unverified
A53: No single framework combines all seven at score ≥ 2. The emergent architecture is COMPOSITE, not unitary.
A54: This candidate architecture provides the analytical reference model against which frameworks, including c-ECO (TFP/TDR), will be compared in Paper 2.

Sheet Coding Manual
A1: CODING MANUAL v1.3 — c-ECO Research Protocol
A2: Anchored examples for each score of each function. Includes POSITIVE examples, NEGATIVE examples, and "Why not N+1?"
A4: Function | B4: Score | C4: Definition | D4: Positive Example (earns this score) | E4: Negative Example (does NOT earn this score) | F4: Why not N+1? | G4: Boundary Note
A5: F1 Operational Architecture | B5: 0 | C5: No design | D5: The work mentions governance only as a wish or future direction, with no structural description. | E5: The work describes a governance board, meeting schedule, and reporting lines. | F5: Because it lacks even abstract mention of structure. To reach 1, it must mention institutional design abstractly. | G5: Design layer
A6: F1 Operational Architecture | B6: 1 | C6: Implementation discussed abstractly | D6: The work says "governance structures should be established" or "institutional design is needed" without specifying roles, triggers, or processes. | E6: The work details who monitors what, who decides, and what happens when a threshold is crossed. | F6: Because it mentions structure but does not specify indicators, roles, or process. To reach 2, it must define at least indicators or roles.
A7: F1 Operational Architecture | B7: 2 | C7: Indicators/steps, no action | D7: The work defines indicators (e.g., credit gap, line loading) and assigns roles (e.g., central bank, grid operator), but does not specify what action follows from a reading. | E7: The work says "early warning is important" without defining who receives the warning or what they do. | F7: Because it defines indicators and roles but lacks executable actions. To reach 3, it must specify triggers, roles, AND actions.
A8: F1 Operational Architecture | B8: 3 | C8: Triggers, roles, actions defined | D8: The ESRB defines: (a) SRISK indicator, (b) national competent authority as actor, (c) capital buffer increase as action, (d) credit gap ≥ 2% as trigger threshold. | E8: The work proposes a "governance framework" with principles but no executable mechanism. | F8: N/A — this is the maximum score.
A10: F2 Decision Protocol | B10: 0 | C10: No protocol | D10: The work describes a risk model but never mentions who decides or on what basis. | E10: The work says "regulators should intervene when systemic risk is high." | F10: Because it lacks any mention of decision-making. To reach 1, it must at least recommend action. | G10: Mechanism, not timing
A11: F2 Decision Protocol | B11: 1 | C11: Recommends action | D11: The work says "early intervention is recommended" or "authorities should act preemptively" without specifying the actor, criterion, or action. | E11: The work states: "When the credit gap exceeds 2%, the national regulator must increase the CCyB by 0.5%." | F11: Because it recommends action but does not specify who, when, or how. To reach 2, it must define at least one of: actor, criterion, or action.
A12: F2 Decision Protocol | B12: 2 | C12: Partial/informal trigger | D12: The work defines a trigger (e.g., "when stress tests show vulnerability") but the actor or action is vague (e.g., "relevant authorities should consider measures"). | E12: The work has no mention of decision-making, triggers, or institutional response. | F12: Because it has a trigger but lacks specificity on actor or action. To reach 3, it must specify WHO acts, on WHAT criterion, with WHAT action.
A13: F2 Decision Protocol | B13: 3 | C13: Executable trigger: who acts, on what criterion | D13: The CCyB rule: (a) WHO = national macroprudential authority, (b) CRITERION = credit gap ≥ 2% (or 0-2% buffer guide), (c) ACTION = increase buffer by 0-2.5% of risk-weighted assets. | E13: The work says "governance should be strengthened" without specifying any of the three elements. | F13: N/A — this is the maximum score.
A15: F3 Cross-Sector Integration | B15: 0 | C15: Single sector | D15: The work studies only banking contagion, only power grid failures, or only water supply risk. | E15: The work analyzes how a flood affects water, energy, and transport infrastructure simultaneously. | F15: Because it focuses on one sector only. To reach 1, it must mention other sectors.
A16: F3 Cross-Sector Integration | B16: 1 | C16: One sector, mentions others | D16: The work focuses on finance but mentions that "spillovers to the real economy may occur." | E16: The work explicitly models coupling between three sectors (e.g., energy-water-transport). | F16: Because it mentions others but does not model or analyze coupling. To reach 2, it must couple two sectors.
A17: F3 Cross-Sector Integration | B17: 2 | C17: Two sectors coupled | D17: The work models interdependencies between power grids and telecommunications, or between finance and housing. | E17: The work is a generic network model with no sectoral specification. | F17: Because it couples two sectors but not three or more. To reach 3, it must be generic to ≥3 interdependent sectors.
A18: F3 Cross-Sector Integration | B18: 3 | C18: Generic to >=3 interdependent sectors | D18: The work proposes a framework applicable to energy, water, transport, telecommunications, and health infrastructure with explicit coupling mechanisms. | E18: The work studies one sector in depth with no mention of others. | F18: N/A — this is the maximum score.
A20: F4 Threshold Dynamics | B20: 0 | C20: No threshold | D20: The work discusses "risk" or "vulnerability" without any concept of a boundary, limit, or critical point. | E20: The work uses the term "tipping point" as a metaphor without quantification. | F20: Because it lacks any threshold concept. To reach 1, it must mention thresholds metaphorically. | G20: NB: ML probability cutoff != threshold dynamics
A21: F4 Threshold Dynamics | B21: 1 | C21: Qualitative/metaphorical | D21: The work uses terms like "tipping point," "breaking point," or "critical load" without numerical specification. | E21: The work defines a static threshold (e.g., "credit gap = 2%") with no dynamic component. | F21: Because it is metaphorical, not quantified. To reach 2, it must define a numerical threshold.
A22: F4 Threshold Dynamics | B22: 2 | C22: Quantified but static | D22: The work defines a fixed threshold (e.g., "dam water level must not exceed 90% capacity") with no update mechanism based on changing conditions. | E22: The work models threshold proximity with velocity and uncertainty bands (e.g., "we are at 85% capacity, rising at 2%/day, with 95% confidence interval"). | F22: Because it is static, not dynamic. To reach 3, it must include proximity, velocity, AND uncertainty.
A23: F4 Threshold Dynamics | B23: 3 | C23: Dynamic: proximity, velocity, uncertainty | D23: The work defines a threshold zone that updates based on (a) current proximity to limit, (b) rate of approach (velocity), and (c) uncertainty bounds (e.g., confidence intervals, ensemble forecasts). | E23: The work defines a single fixed number as "the threshold" with no consideration of dynamics. | F23: N/A — this is the maximum score.
A25: F5 Observability | B25: 0 | C25: No monitoring | D25: The work discusses risk governance without any mention of indicators, sensors, data, or monitoring systems. | E25: The work proposes a set of indicators but does not validate them against actual pre-event data. | F25: Because it lacks any monitoring concept. To reach 1, it must propose indicators.
A26: F5 Observability | B26: 1 | C26: Indicators proposed | D26: The work proposes indicators (e.g., "we suggest monitoring credit growth and asset prices") but does not show that they provide warning before the event. | E26: The work validates that variance and autocorrelation increase before tipping points in multiple empirical systems. | F26: Because indicators are proposed but not validated. To reach 2, it must validate in at least one domain.
A27: F5 Observability | B27: 2 | C27: Validated in one domain | D27: The work shows that a specific indicator (e.g., P-wave detection) provides pre-event warning in one domain (e.g., seismic early warning). | E27: The work shows the same indicator works across multiple domains (seismic, ecological, financial). | F27: Because validation is limited to one domain. To reach 3, it must demonstrate pre-event detection across multiple empirical cases.
A28: F5 Observability | B28: 3 | C28: Leading indicators + pre-event detection | D28: The work demonstrates that the indicator consistently signals BEFORE the critical event across multiple empirical cases, with quantified lead time (e.g., "variance increases 2-3 years before forest dieback"). | E28: The work proposes indicators but only shows they correlate with the event, not that they precede it. | F28: N/A — this is the maximum score.
A30: F6 Ex-Ante Governance | B30: 0 | C30: Post-hoc / recovery | D30: The work focuses on response, recovery, or resilience after the event has occurred (e.g., "build back better," "disaster recovery plans"). | E30: The work says "prevention is better than cure" but does not specify when or how prevention is triggered. | F30: Because it is reactive, not preventive. To reach 1, it must value early action. | G30: Timing, not mechanism
A31: F6 Ex-Ante Governance | B31: 1 | C31: Values acting early | D31: The work states that early action is desirable (e.g., "precautionary principle," "prevention is important") but does not define a protocol for when or how early action occurs. | E31: The work defines explicit criteria for pre-event intervention (e.g., "activate when credit gap > 2%"). | F31: Because it values early action but does not operationalize it. To reach 2, it must define preventive measures.
A32: F6 Ex-Ante Governance | B32: 2 | C32: Partial preventive protocol | D32: The work defines some preventive measures (e.g., "stress testing should be conducted annually") but does not link them to real-time thresholds or triggers. | E32: The work defines a complete decision protocol with explicit pre-event criteria, actor, and action. | F32: Because preventive measures exist but are not linked to real-time triggers. To reach 3, it must define decision before critical point with explicit criteria.
A33: F6 Ex-Ante Governance | B33: 3 | C33: Decision before critical point, explicit criteria | D33: The work defines: (a) the decision must be made before the critical point is reached, (b) the criteria are explicit and measurable, (c) the actor and action are specified. Example: CCyB activation before crisis, with credit gap as criterion. | E33: The work recommends prevention but does not specify when prevention transitions to mandatory action. | F33: N/A — this is the maximum score.
A35: F7 Reversibility | B35: 0 | C35: Ignores | D35: The work discusses risk, damage, or collapse without any mention of whether the state can be reversed. | E35: The work mentions that some damages are irreversible (e.g., biodiversity loss) but does not use this as a decision variable. | F35: Because it ignores reversibility entirely. To reach 1, it must mention irreversibility. | G35: The variable
A36: F7 Reversibility | B36: 1 | C36: Cites irreversibility | D36: The work mentions irreversibility as a property (e.g., "climate tipping points may be irreversible") but does not classify decisions by reversibility. | E36: The work distinguishes between reversible and irreversible states and uses this distinction to guide decision timing. | F36: Because it mentions irreversibility but does not operationalize it. To reach 2, it must distinguish and use reversibility for prioritization.
A37: F7 Reversibility | B37: 2 | C37: Distinguishes reversible/irreversible states | D37: The work classifies risks or outcomes as reversible vs. irreversible (e.g., Renn & Klinke 2004 classification) and uses this to prioritize, but does not define a reversibility window. | E37: The work defines a specific time window within which action can reverse the trajectory, and uses this window as an explicit input to the decision protocol. | F37: Because it distinguishes but does not define a window. To reach 3, it must define a reversibility window as an explicit decision variable.
A38: F7 Reversibility | B38: 3 | C38: Reversibility window as decision variable | D38: The work defines: (a) a reversibility window (time or state space within which action can reverse trajectory), (b) this window is an explicit input to the decision protocol, (c) the protocol specifies different actions for inside vs. outside the window. Example: Duseja 2026 (AI) — "intervene before the irreversibility threshold." | E38: The work acknowledges irreversibility but does not operationalize it as a decision variable. | F38: N/A — this is the maximum score.
A40: CODING PROTOCOL
A41: 1. Read the full text (not just abstract) before scoring.
A42: 2. Score what the work DEMONSTRATES, not what it CLAIMS.
A43: 3. If a work scores N on a function, use the "Why not N+1?" column to justify.
A44: 4. If uncertain between two scores, use the LOWER score (conservative).
A45: 5. Document the evidence (page number, quote) for every score of 2 or 3.
A46: 6. Two independent coders required for scores ≥2. Compute Cohen's kappa.
A47: 7. Disagreements resolved by discussion; if unresolved, use third coder.
A48: 8. All coding decisions are recorded in the Decision Log with evidence source.

Sheet Decision Log
A1: DECISION LOG v1.3 — c-ECO Research Protocol
A2: All methodological changes, score revisions, and structural modifications are recorded here.
A3: Each entry links to the evidence that motivated the decision.
A5: Date | B5: ID | C5: Field | D5: From | E5: To | F5: Reason | G5: Evidence Source | H5: Reference | I5: Decisor
A6: 2026-06-27 | B6: Multiple | C6: Matrix structure | D6: v1.0 (25 cols) | E6: v1.1 (31 cols) | F6: Added Type_v2, Construct scope, Publication status, Limitation verify status, all>=2, all>=1 | G6: User feedback on v1.0 | H6: See user document 2026-06-27 | I6: User
A7: 2026-06-27 | B7: 10 | C7: Type_v2 | D7: Theory | E7: Review/Survey | F7: Reclassification of secondary literature (review/survey article, not primary theory) | G7: Article title contains "survey" | H7: De Bandt & Hartmann 2002, title: "Systemic risk in banking: a survey" | I7: User
A8: 2026-06-27 | B8: 11 | C8: Type_v2 | D8: Theory | E8: Review/Survey | F8: Reclassification of secondary literature | G8: Article title contains "review" | H8: Caccioli et al. 2018, title: "Network models of financial systemic risk: a review" | I8: User
A9: 2026-06-27 | B9: 12 | C9: Type_v2 | D9: Theory | E9: Review/Survey | F9: Reclassification of secondary literature | G9: Article title contains "review" | H9: Galati & Moessner 2013, title: "Macroprudential policy: a literature review" | I9: User
A10: 2026-06-27 | B10: 14 | C10: Type_v2 | D10: Theory | E10: Review/Survey | F10: Reclassification of secondary literature | G10: Article title contains "survey" | H10: Haes Alhelou et al. 2019, title: "A survey on power system blackout..." | I10: User
A11: 2026-06-27 | B11: 16 | C11: Type_v2 | D11: Theory | E11: Review/Survey | F11: Reclassification of secondary literature | G11: Article is a critical review | H11: Osei-Kyei et al. 2021, title: "Critical review of threats affecting CI resilience" | I11: User
A12: 2026-06-27 | B12: 17 | C12: Type_v2 | D12: Theory | E12: Review/Survey | F12: Reclassification of secondary literature | G12: Article is a review and analysis | H12: Curt & Tacnet 2018, title: "Resilience of critical infrastructures: Review and analysis" | I12: User
A13: 2026-06-27 | B13: 18 | C13: Type_v2 | D13: Theory | E13: Review/Survey | F13: Reclassification of secondary literature | G13: Article is a systematic literature review | H13: Mottahedi et al. 2021, title: "The resilience of critical infrastructure systems: A systematic literature review" | I13: User
A14: 2026-06-27 | B14: 23 | C14: Type_v2 | D14: Method | E14: Review/Survey | F14: Reclassification of secondary literature (IoT EWS review) | G14: Article title contains "review" | H14: Esposito et al. 2022, title: "Recent advances in IoT solutions for early warning systems: A review" | I14: User
A15: 2026-06-27 | B15: 25 | C15: Type_v2 | D15: Theory | E15: Review/Survey | F15: Reclassification of secondary literature (earthquake EWS review) | G15: Article title contains "review" | H15: Velazquez et al. 2020, title: "A review of the technical and socio-organizational components of earthquake EWS" | I15: User
A16: 2026-06-27 | B16: 30 | C16: Type_v2 | D16: Theory | E16: Review/Survey | F16: Reclassification of secondary literature (systemic risk from DRR perspective) | G16: Article is a review | H16: Mitra & Shaw 2023, title: "Systemic risk from a disaster management perspective: A review" | I16: User
... A40: 2026-06-27 | B40: Multiple | C40: METHOD FROZEN | D40: Not frozen | E40: FROZEN v1.3 | F40: Methodological architecture is now stable. Only error corrections and corpus expansion permitted. | G40: User assessment: "method is sufficiently mature to be frozen" | H40: See user document 2026-06-27 | I40: User
A42: PENDING DECISIONS (to be resolved in future versions)
A44: Date | B44: ID | C44: Field | D44: Status | E44: Action required | F44: Priority | G44: Evidence Source | H44: Reference | I44: Assigned to
A45: ASAP | B45: 32, 38, 39, 54 | C45: Publication status | D45: Unknown | E45: Verify DOI, editora, peer review status | F45: HIGH | G45: Publication metadata unavailable | H45: See Review Matrix | I45: User
A46: ASAP | B46: 26, 27, 56 | C46: Publication status | D46: Working paper | E46: Verify if peer-reviewed version exists | F46: LOW | G46: SSRN / working paper sources | H46: See Review Matrix | I46: User
A47: Before Paper 1 | B47: All | C47: Limitations | D47: Abstract-paraphrase | E47: Verify verbatim + page number in primary sources | F47: HIGH | G47: All limitation quotes are paraphrased from abstracts | H47: See Review Matrix column W | I47: User
A48: Before Paper 1 | B48: — | C48: Corpus expansion | D48: 60 frameworks | E48: Expand to ~150 frameworks with full-text coding | F48: MEDIUM | G48: Current n=60 insufficient for robust pattern detection | H48: See Analytical Results tab | I48: User + Team
A49: Before Paper 1 | B49: — | C49: Inter-coder reliability | D49: Not calculated | E49: Compute Cohen's kappa for all 7 functions | F49: HIGH | G49: Only one coder; subjectivity uncontrolled | H49: See Coding Manual | I49: User + Second coder
A50: Before Paper 1 | B50: — | C50: PRISMA-ScR | D50: Not documented | E50: Document PRISMA-ScR flow record | F50: HIGH | G50: Required for systematic review reporting | H50: PRISMA-ScR guidelines (Tricco et al. 2018) | I50: User
A51: Before Paper 2 | B51: — | C51: c-ECO positioning | D51: Not in matrix | E51: Score c-ECO (TFP/TDR) against derived functional architecture | F51: MEDIUM | G51: c-ECO excluded from matrix to avoid bias | H51: See STATUS tab | I51: User
A52: Before Paper 2 | B52: — | C52: Non-English literature | D52: Not searched | E52: Verify Portuguese/Spanish/Chinese literature for omission bias | F52: MEDIUM | G52: Search was English-only via Google Scholar | H52: See Research Protocol | I52: User
A53: Before Paper 2 | B53: — | C53: Sensitivity analysis | D53: Not performed | E53: Test robustness: scores ±1, different coders, different sampling | F53: MEDIUM | G53: Scores are provisional; need robustness check | H53: See Analytical Results limitations | I53: User
A54: 2026-06-27 | B54: Multiple | C54: Formula cache | D54: v1.3 (180+49 formulas uncached; Total & H3 blank) | E54: v1.3.1 (workbook recalculated; cached values present) | F54: Audit: file saved without recalculation; Total column and H3 matrix rendered blank until opened | G54: Internal audit 2026-06-27 (recompute from scores) | H54: See Corpus Summary base rates | I54: User+Audit
A55: 2026-06-27 | B55: Analytical Results | C55: Numeric values | D55: F2=35/3; F7=36; P(F7|F2)=16.7%; P(F5|F4)=74.1%/P(F4|F5)=60.6% | E55: F2=32/1; F7=26; P(F7|F2)=9.1%; P(F5|F4)=60.6%/P(F4|F5)=74.1% | F55: Hand-typed interpretive figures did not match (correct) Corpus Summary; two conditional directions were swapped | G55: Corpus Summary distribution + H3 recompute | H55: Corpus Summary A/G; H3 Co-presence | I55: User+Audit
... A59: 2026-06-27 | B59: Multiple | C59: Live formulas | D59: v1.3.2 (229 formulas flattened to static values) | E59: v1.3.3 (live formulas restored: Total, all>=2/all>=1, H3 co-presence; recalculated) | F59: User request: re-include removed formulas so the workbook stays dynamic on data edits | G59: Compared against v1.3.1 formula set (180 Review Matrix + 49 H3) | H59: v1.3.1 reference | I59: User+Audit

Sheet Functional Architecture
A1: FUNCTIONAL ARCHITECTURE v1.3 — EMERGENT RESULT FROM RQ1
A2: This is NOT the c-ECO hypothesis. It is what the literature offers when the strongest observed score per function is combined.
A3: It provides the analytical reference model against which frameworks, including c-ECO (TFP/TDR), will be compared in Paper 2.
A5: RESEARCH QUESTION 1: What functional architecture for operational governance of threshold dynamics exists in the literature?
A7: ═══════════════════════════════════════════════════════════════════════════════════════
A8: A. CANDIDATE FUNCTIONAL ARCHITECTURE — derived from the highest-performing functional implementations identified during preliminary screening
A9: ═══════════════════════════════════════════════════════════════════════════════════════
A11: Function | B11: Strongest Score | C11: Framework(s) | D11: What it provides | E11: What it lacks | F11: Evidence
A12: F1 Operational Architecture | B12: 3 | C12: ESRB/ECB (ID 1) | D12: Institutional design: indicators (SRISK, CCyB), roles (national competent authority), process (annual review, escalation) | E12: Cross-sector applicability (F3=1); reversibility as variable (F7=1) | F12: ESRB Annual Report 2013; Adrian et al. 2019 JF
A13: F2 Decision Protocol | B13: 3 | C13: ESRB/ECB (ID 1) | D13: Executable trigger: WHO (national regulator), WHAT (increase CCyB), WHEN (credit gap ≥ 2%), HOW MUCH (0-2.5% RWA) | E13: Cross-sector applicability (F3=1); dynamic threshold (F4=2, not 3) | F13: ESRB Regulation 1092/2010; BCBS guidance
A14: F3 Cross-Sector Integration | B14: 3 | C14: Planetary Boundaries (ID 2), Buldyrev (ID 3), Rinaldi (ID 4), Centeno (ID 28), Gambhir (ID 32) | D14: Generic applicability to ≥3 interdependent sectors (climate, biodiversity, energy, water, transport, health) | E14: Operational architecture (F1=1 or 0); executable triggers (F2=0 or 1) | F14: Rockstrom et al. 2009; Buldyrev et al. 2010; Rinaldi et al. 2001
A15: F4 Threshold Dynamics | B15: 3 | C15: Scheffer/Dakos (ID 5), Buldyrev (ID 3), Schäfer (ID 15), Planetary Boundaries (ID 2), Lund-Jensen (ID 39) | D15: Dynamic proximity model: variance/autocorrelation as proximity indicator; tolerance parameter α; time-varying thresholds | E15: Cross-sector operationalization (F3=1 or 2); executable triggers (F2=1 or 0) | F15: Scheffer et al. 2009 Nature; Schäfer et al. 2018 Nat Commun; Lund-Jensen 2012
A16: F5 Observability | B16: 3 | C16: Scheffer/Dakos (ID 5), Velazquez (ID 25), Lund-Jensen (ID 39), Wever (ID 40), Esposito (ID 23) | D16: Validated leading indicators with pre-event detection: variance/autocorrelation (2-3 years lead), P-wave detection (seconds), IoT sensors | E16: Governance activation (F2=1 or 0); cross-sector integration (F3=1 or 2) | F16: Scheffer et al. 2009; Velazquez et al. 2020; Esposito et al. 2022
A17: F6 Ex-Ante Governance | B17: 3 | C17: ESRB/ECB (ID 1), Boyd (ID 41), Muiderman (ID 42), Fuerth (ID 43) | D17: Decision before critical point: countercyclical buffers, anticipatory governance, foresight-based planning | E17: Cross-sector operationalization (F3=1); executable triggers in non-financial domains (F2=1) | F17: Adrian et al. 2019; Boyd et al. 2015; Muiderman et al. 2020
A18: F7 Reversibility | B18: 3 | C18: Duseja 2026 (ID 45) | D18: Reversibility window as explicit decision variable: intervene before irreversibility threshold | E18: Physical infrastructure (sector=AI); preprint (unverified); no cross-sector coupling | F18: Duseja 2026 SSRN 6384060 — PREPRINT, UNVERIFIED
A20: ═══════════════════════════════════════════════════════════════════════════════════════
A21: B. ARCHITECTURE GAP ANALYSIS (composite vs. unitary)
A22: ═══════════════════════════════════════════════════════════════════════════════════════
A24: Observation | B24: Implication
A25: The composite architecture requires 7 different frameworks to achieve score 3 on all functions. | B25: No single framework integrates all functions. This is a descriptive finding, not proof of a market gap.
